Workbook

Sheet Özet
A1: Konsept Araştırması – Nexlev verisi, 9 Ekim 2026
A3: KRİTERLER
A4: • Kanal açılışı ≤ 5 ay (2026-05-09 sonrası) – Nexlev 'channelCreatedAfter' + ilk video tarihiyle çapraz kontrol edildi.
A5: • Para kazanma açık (isMonetizationEnabled = true).
A6: • Tahmini aylık AdSense geliri ≥ $1.000 (Nexlev tahmini; sponsorluk/ürün dahil değil).
A8: KAPSAM VE YÖNTEM
A9: 1) search_niche_finder_channels (query='*', yukarıdaki filtreler): Nexlev 1.137 kanal buldu. Ücretsiz plan 24 saatte 5 sorgu izin verdiği için 5 sayfa = 500 kanal çekilebildi (sayfa 1,2,3,4,6).
A10: 2) latest_discovered_faceless_niches (1.000 kanal): yaşı ≤155 gün, monetize, ≥$1.000 olan 71 kanal; 61'i yeni → toplam 561 kanal.
A11: 3) 561 kanalın her birinin son video başlıkları tek tek okunup 101 konsept kümesine elle atandı (Kanallar sayfası 'Konsept' sütunu).
A12: 4) Aday boşluklar için 13 canlı YouTube araması yapıldı (rakip sayısı + kopyaların izlenmesi) ve 1.310 güncel faceless outlier video tarandı → 'Rakip Kontrolleri' sayfası.
A13: 5) 'Konseptler' sayfasında her küme için yeni kanal sayısı/geliri formülle hesaplanır; 'Fırsatlar' sayfası puanlı öneri listesidir.
A15: ÖNEMLİ UYARILAR
... A31: Rakip Kontrolleri – yapılan YouTube aramaları ve sonuçları

Sheet Kanallar
A1: No | B1: Kanal | C1: Link | D1: Konsept kodu | E1: Konsept | F1: Dil | G1: Ülke | H1: Nexlev kategori | I1: Format | J1: Aylık gelir ($) | K1: Abone | L1: Video sayısı | M1: Ort. izlenme/video | N1: Aylık izlenme | O1: Ort. süre (dk) | P1: RPM ($) | Q1: Outlier | R1: AI içerik | S1: İlk video / yaş | T1: Kanal yaşı (gün) | U1: Kaynak | V1: Son videolar (izlenme)
A2: 1 | B2: Senju | C2: YouTube | D2: GAMING | E2: Oyun (Roblox/Minecraft/diğer) | H2: sports, soccer, youtube challenge videos | J2: 64417 | K2: 377000 | L2: 95 | M2: 172500 | N2: 24109973 | O2: 23.1 | P2: 2.67 | Q2: 2.59 | R2: Hayır | S2: 28 gün | T2: 28 | U2: latest | V2: I Did Something Nobody Has Ever Done (338,000) | They Made a Rocket League Clone...I Broke it (243,000) | We Tried the Hardest Custom Map in Rocket League (94,000) | He Sold...Again (15,000)
A3: 2 | B3: 3DVerse 12 | C3: YouTube | D3: ANIM3D | E3: 3D animasyon vitrin/derleme | H3: animation, design, software | J3: 62793 | K3: 40000 | L3: 245 | M3: 4200 | N3: 32704841 | O3: 8.2 | P3: 1.92 | Q3: 0.42 | R3: Hayır | S3: 122 gün | T3: 122 | U3: latest | V3: My 3D Animation Workflow in iClone (4,200)
A4: 3 | B4: 3D_Spectra_YT | C4: YouTube | D4: ANIM3D | E4: 3D animasyon vitrin/derleme | H4: animation, future & discoveries, tech | J4: 51309 | K4: 46000 | L4: 118 | M4: 3000 | N4: 29670317 | O4: 10.9 | P4: 1.73 | Q4: 0.3 | R4: Hayır | S4: 30 gün | T4: 30 | U4: latest | V4: Top Five 3D Animations That Broke the Internet [September Edition] (3,500) | Top 6 3D Animations That Broke the Internet [August Edition] (2,500)
A5: 4 | B5: PopDaBalloon | C5: YouTube | D5: DATING | E5: Flört şovu (Pop the Balloon) özetleri | H5: reality tv, drama, stories | J5: 47833 | K5: 33100 | L5: 238 | M5: 33450 | N5: 9680828 | O5: 23.4 | P5: 4.94 | Q5: 2 | R5: Hayır | S5: 153 gün | T5: 153 | U5: latest | V5: A Toxic Match | She Flew To Chicago And He Repaid Her With A Gold Digger Meme | Pop The Balloon (160,000) | He Manipulated And Then Ghosted Her A Week Later | Pop The Balloon or Find Love | With Arlette Amuli (140,000) | She Matched With Him and Flew to Africa...The Catchup Exposed Everything Pop The Balloon or Findlove (84,000) | A Broken Match💔 | She Did Everything Right And He Had Nothing To Give | Pop The Balloon Catchup EP86 (35,000)
A6: 5 | B6: Judge Jason | C6: YouTube | D6: COPCOURT | E6: Polis suistimali → mahkeme/dava analizi | F6: en | H6: court cases & legal proceedings | I6: commentary | J6: 46580 | K6: 63200 | L6: 26 | M6: 598730.77 | N6: 9244674 | O6: 36.9 | P6: 5.04 | Q6: 9.19 | R6: Hayır | S6: 2026-07-05 | T6: 96 | U6: search | V6: The Most Hated Cop in America FINALLY Gets Punished — 1 Million Dollar Lawsuit! (4,400,000) | Cop Pulls Over the Wrong Man — CAUGHT Lying AGAIN in Court! ($450K Lawsuit) (3,700,000) | Corrupt Cop PLANTS Evidence — His Own Bodycam BACKFIRES in Court! (1,000,000) | The Most Rotten Top Cop Family in America Finally SHUT DOWN in Court! (976,000)
A7: 6 | B7: Crazy Football | C7: YouTube | D7: SPORTS | E7: Spor haber/fan/derleme | H7: soccer, sports, news | J7: 43332 | K7: 128000 | L7: 469 | M7: 3747 | N7: 40133157 | O7: 8.6 | P7: 1.08 | Q7: 0.06 | R7: Hayır | S7: 61 gün | T7: 61 | U7: latest | V7: The Most BRUTAL FINAL in World Cup History (13,000) | Why Everyone Is Calling Argentina "Vargentina" (6,200) | Will Julian Alvarez Join Barcelona?!? (2,400) | FIFA Nightmare Begins as Argentina Starts Brawl in World Cup Final (2,000)
A8: 7 | B8: Deutsche Chroniken | C8: YouTube | D8: HISTDOC | E8: Genel tarih belgeseli | F8: de | G8: DE | H8: history | I8: documentary | J8: 42087 | K8: 43900 | L8: 503 | M8: 46400 | N8: 11999261 | O8: 24.7 | P8: 3.51 | Q8: 0.61 | R8: Evet | S8: 2026-09-06 | T8: 33 | U8: search | V8: Why did Germany lose Silesia? The full story | Documentary (386,000) | Berlin ist keine Stadt – 8 Städte, die man 1920 zusammengezwungen hat (142,000) | Deutsche Nachnamen: Was dein Name über deine Herkunft verrät | Doku (140,000) | The Morgenthau Plan: America’s Plan to Abolish Germany | Documentary (121,000)
A9: 8 | B9: The Last Day | C9: YouTube | D9: DISASTER | E9: Doğal afet / volkan / felaket senaryosu | F9: en | G9: US | H9: future & discoveries | I9: documentary | J9: 42051 | K9: 24800 | L9: 20 | M9: 533315 | N9: 9058524 | O9: 18.2 | P9: 4.64 | Q9: 12.4 | R9: Evet | S9: 2026-08-05 | T9: 65 | U9: search | V9: Nepal's 2026 Disaster Explained: The Glacier That Wiped Out a Valley (4,800,000) | What would happen If the Moon Crashed Into Earth? (1,400,000) | The Wave That Was Taller Than a Skyscraper (1,300,000) | What Would Happen If an Asteroid Hit the Ocean? (1,000,000)
A10: 9 | B10: Dr. Ares Senior | C10: YouTube | D10: SENIORHEALTH | E10: Yaşlılara doktor sağlık tavsiyesi (AI) | F10: en | G10: US | H10: health | I10: educational | J10: 34161 | K10: 75000 | L10: 40 | M10: 215030 | N10: 6888217 | O10: 24.4 | P10: 4.96 | Q10: 2.57 | R10: Evet | S10: 2026-09-05 | T10: 34 | U10: search | V10: Cardiologist Warns: This Sleeping Position Increases STROKE Risk Overnight! (1,700,000) | Cardiologist Warns: Millions Do THIS Every Morning Without Knowing the Risk! (1,100,000) | What Really Happens When You Go Under Anesthesia (905,000) | 5 Common Pills That Secretly Increase Heart Attack & Stroke Risk After 60 (670,000)
A11: 10 | B11: Underwater Earth 4K | C11: YouTube | D11: OCEAN4K | E11: 3 saatlik okyanus/doğa 4K belgesel | F11: en | G11: US | H11: travel documentary | I11: documentary | J11: 33468 | K11: 26900 | L11: 104 | M11: 69775.98 | N11: 2275607 | O11: 191.3 | P11: 14.71 | Q11: 0.79 | R11: Hayır | S11: 2026-06-05 | T11: 126 | U11: search | V11: The Deep Ocean: The Last Unknown World on Earth (3,000,000) | Mariana Trench: What Lives in the Deepest Place on Earth ? (467,000) | Drake Passage: The Most Violent Waterway on Earth (414,000) | Bermuda Triangle: The Ocean Mystery That Still Haunts the World (404,000)
A12: 11 | B12: Mystic Life Stories | C12: YouTube | D12: NDE | E12: Ölüme yakın deneyim (İsa'yı gördüm) | F12: en | G12: US | H12: christianity | I12: stories | J12: 32061 | K12: 9400 | L12: 18 | M12: 109012.76 | N12: 2881532 | O12: 49 | P12: 11.13 | Q12: 0.41 | R12: Hayır | S12: 2026-09-06 | T12: 33 | U12: search | V12: Woman DIED for 19 Minutes, Met JESUS & Revealed a SHOCKING Truth About Trump in OCT. 2026 (1,700,000) | I DIED at 95 & JESUS Exposed a SHOCKING Truth About Black People — Christian Testimony (46,000) | I'm 90 Years Old — I DIED for 8 Minutes & JESUS Revealed America's TERRIFYING Warning for Sep. 2026 (46,000) | I'm 90 Years Old— I DIED for 11 Minutes & JESUS Showed Me AMERICA 's Terrifying OCTOBER 2026 WARNING (35,000)
A13: 12 | B13: States 2050 | C13: YouTube | D13: FUTUREINV | E13: 'Amerika/Japonya/Çin'in yeni icadı herkesi şoke etti' | F13: en | G13: US | H13: future & discoveries | I13: documentary | J13: 31816 | K13: 71100 | L13: 73 | M13: 136977.4 | N13: 6800170 | O13: 23.6 | P13: 4.68 | Q13: 2.48 | R13: Hayır | S13: 2026-07-05 | T13: 96 | U13: search | V13: America's New Flying Invention Is Shocking Everyone (966,000) | America's New Humanoid Robot Is Shocking the Entire World (761,000) | America’s New Invention Could Make Oil Obsolete (747,000) | America's New Weapon Could Destroy Russia and China (628,000)
A14: 13 | B14: Crime Effect | C14: YouTube | D14: TRUECRIME | E14: Gerçek suç belgeseli (anlatı) | F14: en | G14: US | H14: crime | I14: documentary | J14: 30684 | K14: 32500 | L14: 23 | M14: 311539.13 | N14: 6671378 | O14: 25.2 | P14: 4.6 | Q14: 4.9 | R14: Hayır | S14: 2026-09-06 | T14: 33 | U14: search | V14: Texas Nurse Hits 130 MPH at Red Light... Killed 6 Including Pregnant Mom and Infant | Nicole Linton (4,200,000) | 15-Year-Old Baton Rouge Teen Vanished After Confronting 51-Year-Old Predator Over a Girl (535,000) | Her Mother Gave Him Access to Her for Money — 5-Year-Old Kamarie Holland Was Found Dead Hours Later (512,000) | Louisiana Mom Claimed Her Toddler Was Kidnapped...Hours Later, Police Found Him in a Trash Can (476,000)
A15: 14 | B15: InternetJanitor | C15: YouTube | D15: CREATORDRAMA | E15: YouTuber dramaları (MrBeast dosyaları) | F15: en | H15: internet controversies | I15: commentary | J15: 28757 | K15: 25100 | L15: 11 | M15: 704000 | N15: 7308938 | O15: 21.6 | P15: 3.93 | Q15: 45.3 | R15: Hayır | S15: 2026-09-06 | T15: 33 | U15: search | V15: The MrBeast Files Are Really Bad (3,300,000) | The Jack Doherty Files Are Really Bad (1,200,000) | The Victims of MrBeast (956,000) | The Evil Psychology Of MrBeast (536,000)
A16: 15 | B16: Secret State Files | C16: YouTube | D16: ANCIENTWHY | E16: 'Atalarımız nasıl yaşadı / neden X yapıyoruz' soruları | F16: en | H16: history | I16: documentary | J16: 26791 | K16: 46800 | L16: 86 | M16: 88924.42 | N16: 5247184 | O16: 29.4 | P16: 5.11 | Q16: 1.2 | R16: Evet | S16: 2026-07-05 | T16: 96 | U16: search | V16: Before Air Conditioning, How Did Americans Survive the Summer? (992,000) | Before Central Heating, How Did Americans Survive Freezing Winters? (939,000) | America Had No Income Tax Until 1913 — How Was the Government Funded Before That? (879,000) | American Malls Were Once Packed — So What Killed Them? (755,000)
A17: 16 | B17: Baseplate | C17: YouTube | D17: GAMING | E17: Oyun (Roblox/Minecraft/diğer) | H17: roblox, animation, gaming | J17: 26030 | K17: 590000 | L17: 182 | M17: 80000 | N17: 8142426 | O17: 21.4 | P17: 3.2 | Q17: 0.67 | R17: Hayır | S17: 61 gün | T17: 61 | U17: latest | V17: Baseplate Shorts Compilation | Roblox Animation (80,000)
A18: 17 | B18: The Silent Ruins | C18: YouTube | D18: BATTLEGRAVE | E18: Savaş alanı / isimsiz mezar arkeolojisi | F18: en | H18: history | I18: documentary | J18: 25952 | K18: 9250 | L18: 60 | M18: 76752.52 | N18: 3957658 | O18: 30.5 | P18: 6.56 | Q18: 6.76 | R18: Hayır | S18: 2026-08-05 | T18: 65 | U18: search | V18: The Bullet-Riddled Ground of the Little Bighorn Just Got Even Stranger (640,000) | Something About South Dakota's Little Bighorn Battlefield No Longer Makes Sense (516,000) | The Unmarked Graves Of Antietam Battlefield Just Got Even Stranger (412,000) | Archaeologists Unearthed Something in Louisiana That Predates the Egyptian Pyramids (376,000)
A19: 18 | B19: Yucky Stew | C19: YouTube | D19: EBIKEPOV | E19: E-bisiklet POV: ünlü mahalleleri turu | F19: en | G19: US | H19: recreation | I19: vlogs | J19: 25328 | K19: 34800 | L19: 58 | M19: 254956.52 | N19: 5782952 | O19: 20.1 | P19: 4.38 | Q19: 13.6 | R19: Hayır | S19: 2026-08-05 | T19: 65 | U19: search | V19: Riding the SECRET streets of BEL-AIR to CELEBRITY HOMES (E-Bike POV) (1,500,000) | Sunset Boulevard is Dying, Restaurants Are Out Of Business, Miles Of Vacancies & Abandoned Buildings (833,000) | Riding the SECRET streets of the HOLLYWOOD HILLS to CELEBRITY HOMES (E-Bike POV) (828,000) | I TOOK MY E-BIKE DEEP INTO HOLLYWOOD’S EXOTIC CAR STREETS (insane) (501,000)
A20: 19 | B20: Lubo | C20: YouTube | D20: GAMING | E20: Oyun (Roblox/Minecraft/diğer) | F20: fr | G20: FR | H20: minecraft | I20: gaming | J20: 23432 | K20: 71100 | L20: 230 | M20: 272266.67 | N20: 8536248 | O20: 24.1 | P20: 2.75 | Q20: 10.9 | R20: Hayır | S20: 2026-07-05 | T20: 96 | U20: search | V20: We Survived 100 Days on Create with FuzeIII (497,000) | If we say the name of a block... it disappears (481,000) | 100 Players Create 2 CIVILIZATIONS: RICH vs POOR (426,000) | Minecraft but we're blind, deaf, mute, and drunk (423,000)
A21: 20 | B21: MiniFlipThatDrama | C21: YouTube | D21: AIDRAMA | E21: AI kısa drama / 'reborn' [FULL] filmler | F21: en | G21: US | H21: theatre | I21: stories | J21: 22386 | K21: 67400 | L21: 37 | M21: 307837.84 | N21: 4926019 | O21: 85 | P21: 4.54 | Q21: 5.71 | R21: Evet | S21: 2026-07-06 | T21: 95 | U21: search | V21: [FULL] ❤️💥Human Me, Falling for the Vampire I Hate (1,600,000) | [FULL] 💥⚡️Baldur: The Outcast Son of Thunder (1,600,000) | [FULL] 🐺❤️The Alpha King’s Forbidden Luna (1,000,000) | [FULL] 🪄🔥Rise of the Mage God (1,000,000)
A22: 21 | B22: Aussie True Crime | C22: YouTube | D22: TRUECRIME | E22: Gerçek suç belgeseli (anlatı) | F22: en | H22: crime | I22: documentary | J22: 21061 | K22: 6840 | L22: 88 | M22: 31660.18 | N22: 1365231 | O22: 82.9 | P22: 15.43 | Q22: 1.56 | R22: Hayır | S22: 2026-09-06 | T22: 33 | U22: search | V22: Her missing phone exposed the k*ller's lie 📱 | Murder Calls (314,000) | The prison confession that exposed a BURIED secret | Forensic Investigators (213,000) | One tiny bloodstain solved a triple family homicide | Forensic Investigators (173,000) | One tiny clue exposed a serial k*ller 🔬 | Forensic Investigators (149,000)
A23: 22 | B23: Liliana Sun | C23: YouTube | D23: LIVINGIN | E23: 'X'te yaşam' ülke belgeseli | F23: en | G23: US | H23: travel documentary | I23: documentary | J23: 20269 | K23: 40500 | L23: 23 | M23: 1171538.5 | N23: 11039208 | O23: 34.2 | P23: 1.84 | Q23: 68.1 | R23: Hayır | S23: 2026-07-05 | T23: 96 | U23: search | V23: A unique Khanty dwelling that can withstand the most severe cold in the world. Russia. Yamal. (6,300,000) | One Family's Survival in the Endless Hottest Desert in the World. Documentary (3,000,000) | How do the northern Khanty people survive in the harsh Siberian climate of Russia? (1,000,000) | What is life like for a Mongolian family in one of the world's largest deserts? (959,000)
A24: 23 | B24: Silas Investigates | C24: YouTube | D24: TRUECRIME | E24: Gerçek suç belgeseli (anlatı) | F24: en | G24: US | H24: crime | I24: documentary | J24: 19603 | K24: 6480 | L24: 26 | M24: 67819.23 | N24: 1269169 | O24: 115.4 | P24: 15.45 | Q24: 6.62 | R24: Hayır | S24: 2026-09-05 | T24: 34 | U24: search | V24: 10 People Who VANISHED Then REAPPEARED With Strange Stories | Where Were They? (698,000) | 10 People MURDERED After Exposing GOVERNMENT Secrets | Silenced Before They Could Talk (253,000) | 10 Journalists Who DISAPPEARED Chasing ONE Story | They Knew Too Much (161,000) | FAMILIES Who VANISHED Overnight And Were NEVER Found | Where Did They Go? (99,000)
A25: 24 | B25: Nils | C25: YouTube | D25: HISTDOC | E25: Genel tarih belgeseli | F25: en | G25: US | H25: history | I25: documentary | J25: 19531 | K25: 53400 | L25: 7 | M25: 1022142.9 | N25: 4888286 | O25: 42 | P25: 4 | Q25: 21.71 | R25: Hayır | S25: 2026-08-05 | T25: 65 | U25: search | V25: The First Civilization in the World Was Rather Strange (3,300,000) | The Library of Alexandria is Weirder Than You Think (2,000,000) | The Rise and Fall of the World's Most Evil Empire (No AI) (819,000) | The Phoenicians Were Stranger Than You Think (No AI) (456,000)
A26: 25 | B26: The Unseen Earth | C26: YouTube | D26: OCEAN4K | E26: 3 saatlik okyanus/doğa 4K belgesel | F26: en | G26: US | H26: travel documentary | I26: documentary | J26: 19442 | K26: 4270 | L26: 39 | M26: 52856.36 | N26: 1440883 | O26: 180.8 | P26: 13.49 | Q26: 2.94 | R26: Hayır | S26: 2026-09-05 | T26: 34 | U26: search | V26: BLUE PLANET | A Journey Through The Living Ocean | FULL EPISODE | 4K Documentary (493,000) | COASTAL SEAS | Life, Waves and Secrets Along the World’s Shores | FULL DOCUMENTARY (416,000) | DEEP SEA CREATURES | The Strange Life Forms That Rule Earth’s Hidden Worlds | FULL DOCUMENTARY (159,000) | BLUE PLANET II | The Hidden Life That Connects Earth’s Oceans | FULL EPISODE | 4K DOCUMENTTARY (151,000)
A27: 26 | B27: Serious History Compilations | C27: YouTube | D27: HISTDOC | E27: Genel tarih belgeseli | F27: en | G27: US | H27: history | I27: compilation | J27: 19316 | K27: 20000 | L27: 10 | M27: 245200 | N27: 1811501 | O27: 120.7 | P27: 10.66 | Q27: 14.15 | R27: Hayır | S27: 2026-07-06 | T27: 95 | U27: search | V27: 2 Hours of Animated History to Fall Asleep to (NO AI) (1,100,000) | 2 Hours of People Completely Crashing Out in History (276,000) | 2 Hours of History Stories for People who HATE AI SLOP (262,000) | 2.5 Hours of the Greatest Battles in History Animated | Serious History Compilation (187,000)
A28: 27 | B28: Gilded Heart Dramas | C28: YouTube | D28: AIDRAMA | E28: AI kısa drama / 'reborn' [FULL] filmler | F28: en | G28: US | H28: life stories | I28: stories | J28: 19091 | K28: 17200 | L28: 119 | M28: 35553.31 | N28: 2433617 | O28: 84.3 | P28: 7.84 | Q28: 0.34 | R28: Evet | S28: 2026-08-06 | T28: 64 | U28: search | V28: 【FULL】Everyone Thought She Was a Mute Beggar… Until They Found Out She Was a Billionaire CEO (511,000) | 【FULL】He Dumped a Cleaner—She Married the President, Not Knowing She Was the True Heiress (380,000) | 【FULL】She Hid Her True Power… Until a Monster Army Forced Her to Reveal Herself (320,000) | 【FULL】They Humiliated His Genius Wife, Not Knowing She Was an AI Legend (311,000)
A29: 28 | B29: Dad Prevails | C29: YouTube | D29: FAMREVENGE | E29: Aile intikam hikayeleri (yaşlı ebeveyn POV) | F29: en | G29: US | H29: life stories | I29: stories | J29: 18928 | K29: 8119 | L29: 75 | M29: 18930.39 | N29: 1365718 | O29: 141.5 | P29: 13.86 | Q29: 2.56 | R29: Evet | S29: 2026-09-06 | T29: 33 | U29: search | V29: “Your Wife’s Illness Isn’t Our Problem,” My Daughter-in-Law Said — Then 23 Came to My Lake House (132,000) | My Son Abandoned Me At The Airport—Then A Wealthy Woman Whispered, "I Need A Husband. Come With Me." (118,000) | My Son Threw Me Out of His Wedding for His Bride — But What I Said Next...| Family revenge story. (77,000) | My Son Texted “My Flight Was Canceled. Happy 70th.” — Then I Saw Him at the Restaurant |Dad Prevails (64,000)
A30: 29 | B30: Grands Reportages - TF1 | C30: YouTube | D30: NEWSINV | E30: Kurumsal araştırmacı gazetecilik (re-upload) | F30: fr | G30: FR | H30: investigative documentaries | I30: documentary | J30: 18478 | K30: 34900 | L30: 143 | M30: 117088.51 | N30: 6363860 | O30: 53.2 | P30: 2.9 | Q30: 5.4 | R30: Hayır | S30: 2026-07-06 | T30: 95 | U30: search | V30: Baumettes Prison: A Daily Life Under High Tension (1,000,000) | Our exclusive immersion with the Financial BRI! (559,000) | Enquête : ils ont disparu sans laisser d'adresse ! (508,000) | Saint-Maur: Inside a High-Security Prison! (478,000)
A31: 30 | B31: The State Archive | C31: YouTube | D31: CELEB_DEATH | E31: Ünlü ölüm/miras 'son dakika' (Dolly Parton vb) | F31: en | G31: US | H31: life stories | I31: documentary | J31: 18195 | K31: 7180 | L31: 44 | M31: 60029.41 | N31: 1803343 | O31: 32.5 | P31: 10.09 | Q31: 2.79 | R31: Hayır | S31: 2026-09-05 | T31: 34 | U31: search | V31: Why Dolly Parton's Marriage With Carl Dean Was Much Nastier Than You Thought (529,000) | Dolly Parton's Childhood Was Much CRUELER Than You Thought (362,000) | Presley Gerber's Childhood Was Much CRUELER Than You Thought (257,000) | Dolly Parton Was A MONSTER Off Camera (232,000)
A32: 31 | B32: Democratic Live Trust | C32: YouTube | D32: POLITICS | E32: Siyasi tepki / haber (ABD, AB, Meksika) | F32: en | G32: US | H32: pop news & gossip | I32: commentary | J32: 18115 | K32: 9590 | L32: 47 | M32: 66066.18 | N32: 6359149 | O32: 28.1 | P32: 2.85 | Q32: 0.62 | R32: Hayır | S32: 2026-09-06 | T32: 33 | U32: search | V32: Trump ORDERS for Deportation of Jim Carrey after he HUMILIATED Him on Live Tv. (1,300,000) | Morgan Freeman TEARS Trump On Live Tv. It Broke the Internet (593,000) | SNL and Jimmy Kimmel Destroyed Trump on live. It's Hilarious... (248,000) | Don Jr Calls The Cops On Jimmy Kimmel After He EXPOSED him Live on Air. It's Hilarious (139,000)
A33: 32 | B33: Meister Carl Jung | C33: YouTube | D33: SELFHELP | E33: Stoik, Jung, psikoloji, kişisel gelişim | F33: de | G33: DE | H33: self improvement | I33: commentary | J33: 17885 | K33: 20600 | L33: 67 | M33: 39883.58 | N33: 1577186 | O33: 67.7 | P33: 11.34 | Q33: 2.5 | R33: Hayır | S33: 2026-08-06 | T33: 64 | U33: search | V33: HÖR DIR DAS VOR DEM EINSCHLAFEN AN – UND WACHE MORGEN MIT EINEM VÖLLIG NEUEN GEFÜHL AUF | Carl Jung (189,000) | Gib Salz in deine Schuhe und verändere dein Leben für immer (das uralte Geheimnis) | Carl Jung (169,000) | BITTE SO – UND DAS UNIVERSUM WIRD KEINE ANDERE WAHL HABEN, ALS DICH ZU ERHÖREN | Carl Jung (135,000) | Activate Your Vagus Nerve in 4 Minutes and Attract Everything Into Your Life | Carl Jung (129,000)
A34: 33 | B34: BBTV NEW | C34: YouTube | D34: WILDLIFE | E34: Vahşi yaşam (yaşam döngüsü, avcılar) | F34: es | G34: ES | H34: wildlife | I34: documentary | J34: 17823 | K34: 11700 | L34: 14 | M34: 405114.29 | N34: 7648821 | O34: 11.3 | P34: 2.33 | Q34: 31.3 | R34: Evet | S34: 2026-09-06 | T34: 33 | U34: search | V34: Pangolín: 99 Días Desde el Nacimiento Hasta la Supervivencia | Documental del Pangolín (1,400,000) | Halcón Peregrino: 99 Días Desde el Huevo Hasta la Supervivencia | Documental del Halcón Peregrino (849,000) | León: 100 Días Desde el Nacimiento Hasta la Supervivencia | Documental del León (676,000) | Cálao Grande: 99 Días Desde el Huevo Hasta la Supervivencia | Documental del Cálao Grande (607,000)
A35: 34 | B35: JPaniagua Docs | C35: YouTube | D35: FINANCE | E35: Kişisel finans / ekonomisi / nasıl para kazanır | F35: es | G35: MX | H35: business | I35: documentary | J35: 17434 | K35: 38200 | L35: 72 | M35: 104589.03 | N35: 6693242 | O35: 16.2 | P35: 2.6 | Q35: 1.35 | R35: Hayır | S35: 2026-07-06 | T35: 95 | U35: search | V35: How ROSS Works | The $22 BILLION Empire of Clothes and DISCOUNTS (2,900,000) | How TEMU Works | The CHINESE Giant Moving $73 Billion (601,000) | How TAKIS are made | The Mexican SNACK that conquered the United States | US$1.1 billion (508,000) | MONSTER ENERGY: The brand that turned rebellion into BUSINESS | A US$70 billion empire (477,000)
A36: 35 | B36: Bestias Míticas | C36: YouTube | D36: PREHIST | E36: Tarih öncesi / dinozor / derin zaman | F36: es | H36: wildlife | I36: documentary | J36: 16237 | K36: 11200 | L36: 14 | M36: 432050 | N36: 4830846 | O36: 21.4 | P36: 3.36 | Q36: 10.5 | R36: Evet | S36: 2026-07-06 | T36: 95 | U36: search | V36: The 12 MOST TERRIFYING prehistoric monsters in history (3,800,000) | The 42 Extinct Animals That Could Still Be Alive Today | Full Series (563,000) | These Extinct Animals Could Still Be Alive in the Amazon | Complete Series (516,000) | The 6 Prehistoric Animals Found Perfectly Frozen in Ice (341,000)
A37: 36 | B37: Kindly Sleepin' | C37: YouTube | D37: SLEEP | E37: Uyku içerikleri (tarih, bilim, oyun, sohbet) | F37: en | G37: US | H37: minecraft | I37: gaming | J37: 15278 | K37: 40500 | L37: 17 | M37: 130470.59 | N37: 1659822 | O37: 157.6 | P37: 9.2 | Q37: 6.8 | R37: Hayır | S37: 2026-09-06 | T37: 33 | U37: search | V37: Fall Asleep While I Sort 100% Of These Ducks (489,000) | Fall Asleep While I Literally Find A Needle In a Haystack (308,000) | Fall Asleep While I Clean Gross Carpets and Save The World... (299,000) | Fall Asleep While I Build A Waterpark (256,000)
A38: 37 | B38: Bagholder Association | C38: YouTube | D38: BIZFALL | E38: Marka/şirket yükseliş-çöküş (dikey nişler dahil) | F38: en | G38: US | H38: business | I38: documentary | J38: 15086 | K38: 6630 | L38: 42 | M38: 114823.76 | N38: 4041167 | O38: 16.7 | P38: 3.73 | Q38: 3.09 | R38: Hayır | S38: 2026-07-05 | T38: 96 | U38: search | V38: Doritos Is (Finally) Getting What They Deserve... (1,000,000) | Pepsi Is (Finally) Getting What They Deserve… (1,000,000) | Krispy Kreme Is (Finally) Getting What They Deserve... (646,000) | KFC Won the World. So Why Is It Losing America? (468,000)
A39: 38 | B39: Elias Stoltzfus | C39: YouTube | D39: AMISH | E39: Amish topluluğu (göç, yaşam) | F39: en | H39: culture | I39: documentary | J39: 15084 | K39: 7420 | L39: 33 | M39: 137540.85 | N39: 5944153 | O39: 18.6 | P39: 2.54 | Q39: 0.14 | R39: Evet | S39: 2026-08-06 | T39: 64 | U39: search | V39: Thousands of Amish Are Leaving Their Homes — The Reason Will SHOCK You! (3,600,000) | Where Are 400,000 Amish Moving? | The Great Amish Migration Explained (815,000) | Why the Amish Are Quietly Leaving Pennsylvania After 200 Years — The Reason Will SHOCK You! (109,000) | Why Thousands of Amish Families Are Moving — It Started With a School Bus (1,500)
A40: 39 | B40: History Unfiltered | C40: YouTube | D40: NATIVE | E40: Yerli Amerikalı portre/tarih | F40: en | G40: US | H40: history | I40: documentary | J40: 14885 | K40: 6870 | L40: 124 | M40: 123524.95 | N40: 6240889 | O40: 3.5 | P40: 2.39 | Q40: 0.79 | R40: Hayır | S40: 2026-09-15 | T40: 24 | U40: search | V40: The "Afghan Mona Lisa" in 2026: What Happened to Sharbat Gula? (2,000,000) | Wild Beauty: The New Generation of Native America 🦅🪶🌿 #NativeAmerican (179,000) | The Most Beautiful Native American Faces Portrait Collection #nativeamerican #portrait (93,000) | From War Paint to Runway: Native America Today #NativeAmerican #NativeAmericans (39,000)
...

Sheet Konseptler
A1: Kod | B1: Konsept | C1: Yeni kanal sayısı | D1: Toplam aylık gelir ($) | E1: Ort. gelir/kanal ($) | F1: En yüksek kanal geliri ($) | G1: Doygunluk (yeni kanal sayısına göre) | H1: Dış kontrol (YouTube arama) | I1: Kanallar (No)
A2: AIDRAMA | B2: AI kısa drama / 'reborn' [FULL] filmler | C2: =COUNTIF(Kanallar!$D$2:$D$562,A2) -> 23 | D2: =SUMIF(Kanallar!$D$2:$D$562,A2,Kanallar!$J$2:$J$562) -> 162108 | E2: =IF(C2=0,0,D2/C2) -> 7048.1739 | F2: =_xlfn.MAXIFS(Kanallar!$J$2:$J$562,Kanallar!$D$2:$D$562,A2) -> 22386 | G2: =IF(C2>=6,"Dolu (6+)",IF(C2>=3,"Kısmen dolu (3-5)","Az rakip (1-2)")) -> Dolu (6+) | H2: — | I2: #20, #27, #44, #55, #70, #74, #93, #108, #109, #112, #126, #149, #211, #227, #269, #294, #386, #398, #507, #516, #526, #528, #560
A3: GAMING | B3: Oyun (Roblox/Minecraft/diğer) | C3: =COUNTIF(Kanallar!$D$2:$D$562,A3) -> 16 | D3: =SUMIF(Kanallar!$D$2:$D$562,A3,Kanallar!$J$2:$J$562) -> 161834 | E3: =IF(C3=0,0,D3/C3) -> 10114.625 | F3: =_xlfn.MAXIFS(Kanallar!$J$2:$J$562,Kanallar!$D$2:$D$562,A3) -> 64417 | G3: =IF(C3>=6,"Dolu (6+)",IF(C3>=3,"Kısmen dolu (3-5)","Az rakip (1-2)")) -> Dolu (6+) | H3: — | I3: #1, #16, #19, #98, #195, #201, #230, #231, #233, #293, #307, #378, #423, #442, #471, #513
A4: TRUECRIME | B4: Gerçek suç belgeseli (anlatı) | C4: =COUNTIF(Kanallar!$D$2:$D$562,A4) -> 17 | D4: =SUMIF(Kanallar!$D$2:$D$562,A4,Kanallar!$J$2:$J$562) -> 132046 | E4: =IF(C4=0,0,D4/C4) -> 7767.4118 | F4: =_xlfn.MAXIFS(Kanallar!$J$2:$J$562,Kanallar!$D$2:$D$562,A4) -> 30684 | G4: =IF(C4>=6,"Dolu (6+)",IF(C4>=3,"Kısmen dolu (3-5)","Az rakip (1-2)")) -> Dolu (6+) | H4: — | I4: #13, #21, #23, #53, #80, #116, #171, #183, #225, #309, #360, #435, #455, #493, #529, #543, #554
A5: FAMREVENGE | B5: Aile intikam hikayeleri (yaşlı ebeveyn POV) | C5: =COUNTIF(Kanallar!$D$2:$D$562,A5) -> 17 | D5: =SUMIF(Kanallar!$D$2:$D$562,A5,Kanallar!$J$2:$J$562) -> 126084 | E5: =IF(C5=0,0,D5/C5) -> 7416.7059 | F5: =_xlfn.MAXIFS(Kanallar!$J$2:$J$562,Kanallar!$D$2:$D$562,A5) -> 18928 | G5: =IF(C5>=6,"Dolu (6+)",IF(C5>=3,"Kısmen dolu (3-5)","Az rakip (1-2)")) -> Dolu (6+) | H5: — | I5: #28, #42, #47, #61, #68, #107, #128, #144, #151, #161, #190, #241, #264, #308, #370, #446, #476
A6: HISTDOC | B6: Genel tarih belgeseli | C6: =COUNTIF(Kanallar!$D$2:$D$562,A6) -> 17 | D6: =SUMIF(Kanallar!$D$2:$D$562,A6,Kanallar!$J$2:$J$562) -> 116808 | E6: =IF(C6=0,0,D6/C6) -> 6871.0588 | F6: =_xlfn.MAXIFS(Kanallar!$J$2:$J$562,Kanallar!$D$2:$D$562,A6) -> 42087 | G6: =IF(C6>=6,"Dolu (6+)",IF(C6>=3,"Kısmen dolu (3-5)","Az rakip (1-2)")) -> Dolu (6+) | H6: — | I6: #7, #24, #26, #188, #194, #251, #281, #369, #393, #401, #402, #486, #497, #503, #523, #536, #538
A7: ANIM3D | B7: 3D animasyon vitrin/derleme | C7: =COUNTIF(Kanallar!$D$2:$D$562,A7) -> 2 | D7: =SUMIF(Kanallar!$D$2:$D$562,A7,Kanallar!$J$2:$J$562) -> 114102 | E7: =IF(C7=0,0,D7/C7) -> 57051 | F7: =_xlfn.MAXIFS(Kanallar!$J$2:$J$562,Kanallar!$D$2:$D$562,A7) -> 62793 | G7: =IF(C7>=6,"Dolu (6+)",IF(C7>=3,"Kısmen dolu (3-5)","Az rakip (1-2)")) -> Az rakip (1-2) | H7: — | I7: #2, #3
A8: DISASTER | B8: Doğal afet / volkan / felaket senaryosu | C8: =COUNTIF(Kanallar!$D$2:$D$562,A8) -> 11 | D8: =SUMIF(Kanallar!$D$2:$D$562,A8,Kanallar!$J$2:$J$562) -> 92030 | E8: =IF(C8=0,0,D8/C8) -> 8366.3636 | F8: =_xlfn.MAXIFS(Kanallar!$J$2:$J$562,Kanallar!$D$2:$D$562,A8) -> 42051 | G8: =IF(C8>=6,"Dolu (6+)",IF(C8>=3,"Kısmen dolu (3-5)","Az rakip (1-2)")) -> Dolu (6+) | H8: — | I8: #8, #50, #122, #145, #193, #213, #246, #298, #374, #469, #556
A9: SPORTS | B9: Spor haber/fan/derleme | C9: =COUNTIF(Kanallar!$D$2:$D$562,A9) -> 14 | D9: =SUMIF(Kanallar!$D$2:$D$562,A9,Kanallar!$J$2:$J$562) -> 78664 | E9: =IF(C9=0,0,D9/C9) -> 5618.8571 | F9: =_xlfn.MAXIFS(Kanallar!$J$2:$J$562,Kanallar!$D$2:$D$562,A9) -> 43332 | G9: =IF(C9>=6,"Dolu (6+)",IF(C9>=3,"Kısmen dolu (3-5)","Az rakip (1-2)")) -> Dolu (6+) | H9: — | I9: #6, #115, #170, #197, #316, #406, #443, #468, #484, #487, #496, #545, #555, #558
A10: ANCIENTWHY | B10: 'Atalarımız nasıl yaşadı / neden X yapıyoruz' soruları | C10: =COUNTIF(Kanallar!$D$2:$D$562,A10) -> 12 | D10: =SUMIF(Kanallar!$D$2:$D$562,A10,Kanallar!$J$2:$J$562) -> 77399 | E10: =IF(C10=0,0,D10/C10) -> 6449.9167 | F10: =_xlfn.MAXIFS(Kanallar!$J$2:$J$562,Kanallar!$D$2:$D$562,A10) -> 26791 | G10: =IF(C10>=6,"Dolu (6+)",IF(C10>=3,"Kısmen dolu (3-5)","Az rakip (1-2)")) -> Dolu (6+) | H10: — | I10: #15, #40, #102, #143, #305, #312, #325, #362, #382, #394, #436, #518
A11: SLEEP | B11: Uyku içerikleri (tarih, bilim, oyun, sohbet) | C11: =COUNTIF(Kanallar!$D$2:$D$562,A11) -> 12 | D11: =SUMIF(Kanallar!$D$2:$D$562,A11,Kanallar!$J$2:$J$562) -> 74529 | E11: =IF(C11=0,0,D11/C11) -> 6210.75 | F11: =_xlfn.MAXIFS(Kanallar!$J$2:$J$562,Kanallar!$D$2:$D$562,A11) -> 15278 | G11: =IF(C11>=6,"Dolu (6+)",IF(C11>=3,"Kısmen dolu (3-5)","Az rakip (1-2)")) -> Dolu (6+) | H11: — | I11: #36, #41, #77, #153, #174, #177, #206, #279, #355, #391, #433, #522
A12: FUTUREINV | B12: 'Amerika/Japonya/Çin'in yeni icadı herkesi şoke etti' | C12: =COUNTIF(Kanallar!$D$2:$D$562,A12) -> 11 | D12: =SUMIF(Kanallar!$D$2:$D$562,A12,Kanallar!$J$2:$J$562) -> 73173 | E12: =IF(C12=0,0,D12/C12) -> 6652.0909 | F12: =_xlfn.MAXIFS(Kanallar!$J$2:$J$562,Kanallar!$D$2:$D$562,A12) -> 31816 | G12: =IF(C12>=6,"Dolu (6+)",IF(C12>=3,"Kısmen dolu (3-5)","Az rakip (1-2)")) -> Dolu (6+) | H12: — | I12: #12, #104, #166, #205, #207, #217, #259, #329, #365, #428, #506
A13: BIZFALL | B13: Marka/şirket yükseliş-çöküş (dikey nişler dahil) | C13: =COUNTIF(Kanallar!$D$2:$D$562,A13) -> 12 | D13: =SUMIF(Kanallar!$D$2:$D$562,A13,Kanallar!$J$2:$J$562) -> 70554 | E13: =IF(C13=0,0,D13/C13) -> 5879.5 | F13: =_xlfn.MAXIFS(Kanallar!$J$2:$J$562,Kanallar!$D$2:$D$562,A13) -> 15086 | G13: =IF(C13>=6,"Dolu (6+)",IF(C13>=3,"Kısmen dolu (3-5)","Az rakip (1-2)")) -> Dolu (6+) | H13: Golf dikeyi: tek lider (Persimmon) → DİKEYDE AÇIK | I13: #37, #65, #79, #95, #105, #287, #340, #343, #403, #407, #434, #464
... A102: MINIATURE | B102: Karton minyatür ev yapımı | C102: =COUNTIF(Kanallar!$D$2:$D$562,A102) -> 1 | D102: =SUMIF(Kanallar!$D$2:$D$562,A102,Kanallar!$J$2:$J$562) -> 1113 | E102: =IF(C102=0,0,D102/C102) -> 1113 | F102: =_xlfn.MAXIFS(Kanallar!$J$2:$J$562,Kanallar!$D$2:$D$562,A102) -> 1113 | G102: =IF(C102>=6,"Dolu (6+)",IF(C102>=3,"Kısmen dolu (3-5)","Az rakip (1-2)")) -> Az rakip (1-2) | H102: — | I102: #548
B103: TOPLAM | C103: =SUM(C2:C102) -> 561 | D103: =SUM(D2:D102) -> 3348213
B104: Doygunluk eşiği: aynı kümede son 5 ayda açılmış ve ≥$1K/ay kazanan kanal sayısı (yalnız bu veri setinde). Dış kontrol sütunu canlı YouTube aramasından elle yazıldı.

Sheet Fırsatlar
A1: Sıra | B1: Konsept / fırsat | C1: Tip | D1: Kanıt (kanal no = Kanallar sayfası) | E1: Rakip kontrolü | F1: Önerilen açı / içerik planı | G1: Risk | H1: Puan (1-10)
A2: 1 | B2: Görünmeyen Amerika – faceless yoksulluk/motel/Appalachia belgeselleri | C2: Kanıtlı boşluk (1 kanal) | D2: Stateside Stories (#46) $13.7K/ay, 20K abone, 30 video; 'America's Motel Families' 1.6M | E2: Talep devasa (Drew Binsky, RocaNews 10M+), faceless rakip neredeyse yok | F2: Arşiv/stok + harita + veri anlatımı; 'Inside America's ___' serisi: motel aileleri, karavan parkları, şirket kasabaları, Native rezervasyonlar, gıda çölleri. 40-55 dk. | G2: Stok görüntü bulmak zor; etik/hassas dil | H2: 9
A3: 2 | B3: Hobi-dikey marka yükseliş & çöküş (golf dışında) | C3: Yeni konsept (kanıtlı şablon) | D3: Persimmon Archive (#287) golf $3.5K; Lost American Footwear sneaker outlier 211K (0 abone); Mr. Watchman (#343) saat $2.8K; House of Ruin (#407) moda $2.3K; Imperios del Sonido (#105, ES) elektronik $8.2K | E3: Golf aramasında Persimmon tek lider, kopyalar 400-9K. Diğer dikeylerde bulunamadı | F3: Her dikey ayrı kanal: Olta/balıkçılık (Zebco, Abu Garcia), gitar (Gibson, Peavey), fotoğraf makinesi (Minolta, Polaroid), av tüfeği (Remington, Winchester), motosiklet (Indian, Excelsior), bisiklet (Schwinn), elektrikli alet (Craftsman), karavan (Winnebago). 55+ erkek hobi kitlesi = yüksek RPM. | G3: The Fall Files ile örtüşme riski – dikey hobi kitlesine odaklanarak ayrıştır | H3: 9
A4: 3 | B4: Eyalet-özel tarih kanalı ('Ohio Uncovered' şablonu) | C4: Kanıtlı boşluk (1 kanal) | D4: Ohio Uncovered (#89) $9.1K/ay, sadece 17 video, 7K abone ('10 Places in Ohio the Mob Used to Control' 426K) | E4: Aranmadı; veri setinde başka eyalet kanalı yok | F4: Pennsylvania/Michigan/Texas/Kentucky Uncovered: mafya yerleri, her ilçenin en ünlü kişisi, eski para semtleri, kaybolan kasabalar. Yerel gurur = paylaşım. | G4: Her eyalet kitlesi sınırlı; çok kanal ağı kurulabilir | H4: 8
A5: 4 | B5: Kore / Vietnam / unutulan savaşlar belgeseli | C5: Yeni konsept | D5: 38th Parallel Files (outlier, 0K abone, 'Pork Chop Hill 1953' 286K); WW2 kümesinde 14 yeni kanal = WW2 doymuş | E5: WW2 kalabalık; Kore Savaşı için tek outlier kanal görüldü | F5: Kore Savaşı, Vietnam, Falkland, Boer, Rus-Japon savaşı. WW2'deki 'Japonlar güldü – ta ki...' şablonunu Kore'ye taşı. | G5: Arşiv görüntü kısıtlı | H5: 8
A6: 5 | B6: E-bisiklet POV ünlü mahalleleri (başka şehirler) | C6: Kanıtlı boşluk (1 kanal) | D6: Yucky Stew (#18) $25.3K/ay, 34K abone, 58 video | E6: AÇIK – YouTube aramasında tek ciddi kanal | F6: Miami (Star Island), Nashville country yıldız evleri, Atlanta, Hamptons, Londra Kensington, Dubai. 4K POV çekim. | G6: Faceless ama yerinde çekim gerektirir (AI ile yapılamaz) | H6: 8
A7: 6 | B7: Hemşirelik / sağlık sınavı hazırlık (NCLEX, EMT, CNA) | C7: Kanıtlı boşluk (1 kanal) | D7: Qumal Fafma (#52) $13.1K/ay, sadece 6 video, 2.7M izlenmeli video | E7: Aranmadı; veri setinde tek | F7: Animasyonlu ilaç dozları, iğne boyutları, laboratuvar değerleri ezber teknikleri. Eğitim = çok yüksek RPM + evergreen. | G7: Doğruluk sorumluluğu (uzman kontrolü şart) | H7: 8
A8: 7 | B8: Klasik TV derin bilgi (55+ kitle) | C8: Yeni konsept | D8: Curtain Cut outlier ('The REAL Reason the Professor Never Fixed the Boat' 437K, 0 abone; '70'lerin unutulan süper kahraman dizileri' 234K); Rewatch TV (#43) $14K; Rewind Facts outlier | E8: Klasik TV 'kötü yıldız' listeleri dolu (#179,#303) ama dizi-içi lore/trivia boş | F8: Gilligan's Island, Bonanza, M*A*S*H, Andy Griffith, Twilight Zone: 'gerçek sebep', 'çekim arkası', 'silinen sahne'. TV izleyen yaşlı ABD kitlesi. | G8: Klip telif riski – görsel AI/still ile | H8: 8
A9: 8 | B9: Kapalı topluluklar (Amish'in ötesi) | C9: Komşu boşluk | D9: Elias Stoltzfus (#38) $15K/ay, 7K abone; Amish videosu 3.7M | E9: Amish konusu kopyalarla doldu (10+ kanal ama 0-2K izlenme). Mennonit/Hutterit/Hasidik/FLDS için kanal görülmedi | F9: Hutterites, Mennonitler, Old Order, Hasidik Yahudiler, Doukhobor, Shakers tarihi. 'Neden göç ediyorlar / nasıl para kazanıyorlar'. | G9: Hassas dini konular; saygılı ton | H9: 7
A10: 9 | B10: Savaş alanı mezar arkeolojisi (İç Savaş dışı) | C10: Kısmen açık | D10: The Silent Ruins (#17) $26K/ay, 9K abone | E10: Antietam/Gettysburg kopyalandı (kopyalar 4-36K alıyor) | F10: WW1 Batı Cephesi, Pasifik adaları, Vahşi Batı katliam alanları, gemi enkazı mezarları. 'Just Got Even Stranger' kalıbı. | G10: Kopya kanallar hızla geliyor | H10: 7
A11: 10 | B11: İspanyolca/Almanca/Fransızca port (dil arbitrajı) | C11: Yeni konsept | D11: ES/DE/FR kanalları veri setinin %18'i; ES'de 'marka alma' (#67 $10.8K, #101 $8.5K), DE'de soyadı (#336) ve tarih (#7 $42K!) | E11: Rakip yoğunluğu EN'e göre çok düşük | F11: Kanıtlı EN formatlarını DE/FR'ye taşı: Görünmeyen Almanya, Alman marka çöküşleri (#434 var), Fransız 'Lost' nostalji (#464 var). Deutsche Chroniken (#7) $42K/ay = DE tarih çok kârlı. | G11: Ana dil seviyesinde senaryo gerekir | H11: 7
A12: 11 | B12: Ölüme yakın deneyim (NDE) anlatıları | C12: Kanıtlı (az kanal) – dış kontrol yapılmadı | D12: Mystic Life Stories (#11) $32K/ay (9K abone, 1 video 1.7M), When You Die (#286) $3.6K | E12: Aranmadı (kota) – ilk kontrol edilmesi gereken | F12: Yaşlı anlatıcı + 'X dakika öldüm ve gördüm' hikayeleri; Hristiyan kitle + uyku/uzun format. İspanyolca versiyonu da düşünülebilir. | G12: Gelir tek bir viral videoya dayanıyor olabilir | H12: 7
A13: 12 | B13: Cozy kamu malı dedektif uyku gizemleri (Holmes dışı) | C13: Kısmen açık | D13: Holmes Legacy (#452) $1.9K, 221B Archive (#453) $1.9K – ikisi de 1-3K abone | E13: Holmes için 4-5 küçük kanal; Father Brown/Dupin/Thorndyke için yok | F13: Father Brown, Auguste Dupin, Dr. Thorndyke, Sexton Blake, Craig Kennedy – 2 saatlik uyku gizemleri. | G13: Gelir düşük-orta; uzun video üretim maliyeti | H13: 6
... A23: 22 | B23: Kamyoncu dünyası | C23: Kanıtlı boşluk (1 kanal) | D23: Trucker Life (#392) $2.5K ('20 U.S. Rest Areas So DANGEROUS' 475K) | E23: Aranmadı | F23: Tehlikeli yollar, köprüler, kamyoncu efsaneleri, kayıp kamyon hikayeleri. | G23: Düşük-orta gelir | H23: 5
B25: Puan = talep kanıtı (kanal geliri/outlier) + rakip azlığı + faceless/AI üretilebilirlik + RPM tahmini; benim değerlendirmem (sarı hücreler değiştirilebilir).

Sheet Rakip Kontrolleri
A1: Arama sorgusu | B1: Tarih filtresi | C1: Bulgular | D1: Sonuç
A2: riding bike through celebrity neighborhoods homes | B2: Yıl | C2: Yucky Stew tek ciddi oyuncu (1.6M, 857K, 514K); diğerleri vlog/alakasız. | D2: AÇIK – tek kanal
A3: Sherlock Holmes mystery full story sleep | B3: Ay | C3: What If SleepStorian (1-7K), 221B Stories (15K), Watson's Journal (~0), Midnight Time Traveller (2K). Toplam ~396 sonuç. | D3: KISMEN AÇIK – 4-5 küçük kanal, kimse büyümemiş
A4: Amish leaving why | B4: Ay | C4: Elias Stoltzfus 3.7M; Amish Faith Today 86-105K; 10+ kopya kanal 0-2K izlenme. | D4: KOPYA DOLU – orijinal kazanıyor, kopyalar ölü
A5: battlefield unmarked graves just got even | B5: Yıl | C5: Silent Ruins 455K; Below the Floor 36K, Relics of America 17K, Redline 4K; birebir kopyalar. | D5: KISMEN AÇIK – kopyalar 17-36K alabiliyor
A6: what happened to his children after he was overthrown | B6: Yıl | C6: After the Crown 675K; ~15 kopya (RU/DE/ES/AR çeviri dahil) çoğu <3K. | D6: KOPYA DOLU – kazanan tek
A7: corrupt cop caught lying in court lawsuit judge | B7: Ay (uzun) | C7: Justice Brief 382K, Court Unsealed 15K; 15+ kopya 0-500 izlenme (aynı başlıklar). | D7: DOLU – kazanan-hepsini-alır
A8: America's motel families poverty documentary | B8: Yıl (uzun) | C8: Talep çok yüksek (Drew Binsky 9.8M/14M, RocaNews 12M, Witness 560K) ama faceless kanal yok denecek kadar az (Professor Maple 96 izlenme). | D8: AÇIK – talep var, faceless arz yok
A9: 60 year old carpenter wood trick genius idea | B9: Ay | C9: Maker Wood Master (797K), Wood Creation (286K), Unknown Tricks (1.4M), Clever Maker (212K), DIY WoodSpark, woodworking Tips – ~6 kanal, hepsi izlenme alıyor. | D9: KISMEN DOLU – ama yeni giren de izlenme alıyor
A10: deep ocean 4K documentary 3 hours relaxing | B10: Ay (uzun) | C10: Underwater Earth 4K 70K; onlarca yeni kanal 12-2.000 izlenme. | D10: DOLU
A11: why nobody wants to visit anymore | B11: Ay | C11: Forgotten British Cities 97K, MrHousing 90K, The Faded Coast 67K, Grand Manors 20K, Industrial South 25K, After The Prime 103K – ~8 kanal, çoğu iyi gidiyor. | D11: KISMEN AÇIK – format büyüyor, bölgeler paylaşılıyor
A12: the economics of owning a | B12: Ay | C12: THE OWNERS, Lucas Economics, Mr. Finance, Ownership Lab, Cost Anatomy, Useless Money... 15+ kanal, çoğu <10K. | D12: DOLU
... A15: faceless_outliers (Eylül 2026+, <20K abone, >200K izlenme, EN, uzun) | B15: Eylül-Ekim | C15: 1.310 outlier video. Dikkat çekenler: Curtain Cut (0 abone, Gilligan's Island 437K), 38th Parallel Files (Kore Savaşı 286K), Lost American Footwear (sneaker marka çöküşü 211K), Nature's Tether (bölgesel vahşi yaşam 445K), Mr Isles (İngiliz emekliler 209K), Jonathan Funk (Social Security 501K), Vintage Trains (204K). | D15: Yeni konsept sinyalleri
